Workbook

Sheet OMOP>>

Sheet Fields
B2: Concept ID | C2: Concept | D2: Carrot Table | E2: OMOP Table | F2: Source Field | G2: Description | H2: Source Table
B3: 44806614 | C3: Child protection category emotional | D3: cp_plain_fact_1 | E3: observation | F3: CP_CATEGORY_EMOTIONAL | G3: CP reason flag emotional | H3: CP_PLAIN_FACT.csv
B4: 44806612 | C4: Child protection category neglect | D4: cp_plain_fact_1 | E4: observation | F4: CP_CATEGORY_NEGLECT | G4: CP reason flag neglect | H4: CP_PLAIN_FACT.csv
B5: 44806615 | C5: Child protection category physical | D5: cp_plain_fact_1 | E5: observation | F5: CP_CATEGORY_PHYSICAL | G5: CP reason flag physical | H5: CP_PLAIN_FACT.csv
B6: 44806613 | C6: Child protection category sexual | D6: cp_plain_fact_1 | E6: observation | F6: CP_CATEGORY_SEXUAL | G6: CP reason flag sexual | H6: CP_PLAIN_FACT.csv
B7: 4053115 | C7: Child removed from protection register | D7: cp_plain_fact_2 | E7: observation | F7: CP_END_DATE | G7: End date | H7: CP_PLAIN_FACT.csv
B8: N/A | C8: N/A | D8: cp_plain_fact_1 | E8: observation | F8: CP_START_DATE | G8: Start date | H8: CP_PLAIN_FACT.csv
B9: 44791869 | C9: Social services care planning | D9: strat_disc | E9: procedure | F9: MEETING_DATE | G9: Meeting date | H9: STRATEGY_DISCUSSION_FACT.csv
B10: 1620966 | C10: No further follow-up | D10: strat_disc | E10: measurement | F10: STR_DIS_OUTCOME_NFA | G10: Outcome flag no further action | H10: STRATEGY_DISCUSSION_FACT.csv
B11: 4189812 | C11: Police investigation | D11: strat_disc | E11: observation | F11: STR_DIS_OUTCOME_POLICE_INVESTIGATION | G11: Outcome flag police investigation | H11: STRATEGY_DISCUSSION_FACT.csv
B12: 4137059 | C12: Transfer out of area | D12: strat_disc | E12: observation | F12: STR_DIS_OUTCOME_REF_OTHER_AGENCY | G12: Outcome flag referral to other agency | H12: STRATEGY_DISCUSSION_FACT.csv
B13: 44795391 | C13: Child protection investigation | D13: strat_disc | E13: procedure_occurrence | F13: STR_DIS_OUTCOME_S47_INVESTIGATION | G13: Outcome flag S47 investigation | H13: STRATEGY_DISCUSSION_FACT.csv
B14: 44787796 | C14: Single assessment process | D14: strat_disc | E14: procedure_occurrence | F14: STR_DIS_OUTCOME_SINGLE_ASSESSMENT | G14: Outcome flag single assessment | H14: STRATEGY_DISCUSSION_FACT.csv
B15: N/A | C15: N/A | D15: single_assessment_end | E15: observation | F15: ﻿ASSESSMENT_END_DATE | G15: Assessment end date. | H15: SINGLE_ASSESSMENT_FACT.csv
B16: 44787796 | C16: Single assessment process | D16: single_assessment | E16: procedure_occurrence | F16: ASSESSMENT_START_DATE | G16: Assessment start date. | H16: SINGLE_ASSESSMENT_FACT.csv
B17: 44813501 | C17: Looked after child [with qualifier] request for | D17: single_assessment_cla | E17: observation | F17: ASSESS_OUTCOME_CLA_REQUEST | G17: Outcome flag CLA (looked after child) request | H17: SINGLE_ASSESSMENT_FACT.csv
B18: 4139252 | C18: Legal proceedings | D18: single_assessment | E18: observation | F18: ASSESS_OUTCOME_LEGAL_ACTION | G18: Outcome flag legal action | H18: SINGLE_ASSESSMENT_FACT.csv
B19: 1620966 | C19: No further follow-up | D19: single_assessment | E19: measurement | F19: ASSESS_OUTCOME_NFA | G19: Outcome flag no further action | H19: SINGLE_ASSESSMENT_FACT.csv
B20: 4053115 | C20: Child removed from protection register | D20: single_assessment | E20: observation | F20: ASSESS_OUTCOME_SFA_S47_END | G20: Outcome flag end S47 | H20: SINGLE_ASSESSMENT_FACT.csv
B21: 44811639 | C21: Child in private foster care | D21: single_assessment | E21: observation | F21: ASSESS_OUTCOME_PRIV_FOSTERING | G21: Outcome flag private fostering | H21: SINGLE_ASSESSMENT_FACT.csv
B22: 4148671 | C22: Social services | D22: single_assessment | E22: observation | F22: ASSESS_OUTCOME_PROVISION_OF_SERVICE | G22: Outcome flag provision of service | H22: SINGLE_ASSESSMENT_FACT.csv
B23: 4019826 | C23: Respite care of patient | D23: single_assessment | E23: observation | F23: ASSESS_OUTCOME_PROV_SB_CARE | G23: Outcome flag provision of short break care | H23: SINGLE_ASSESSMENT_FACT.csv
B24: 4208328 | C24: Referral to [with qualifier] Agency | D24: single_assessment | E24: observation | F24: ASSESS_OUTCOME_REF_OTHER_AGENCY | G24: Outcome flag referral to other agency | H24: SINGLE_ASSESSMENT_FACT.csv
B25: 44798918 | C25: Social services specialist assessment | D25: single_assessment | E25: procedure_occurrence | F25: ASSESS_OUTCOME_SPECIALIST_ASSESS | G25: Outcome flag specialist assessment | H25: SINGLE_ASSESSMENT_FACT.csv
B26: 4073156 | C26: Discussion | D26: single_assessment | E26: procedure_occurrence | F26: ASSESS_OUTCOME_STRATEGY_DISCUSSION | G26: Outcome flag strategy discussion | H26: SINGLE_ASSESSMENT_FACT.csv
B27: N/A | C27: Map as the provider associated with the assessment | D27: single_assessment_provider | E27: provider | F27: COMPLETED_BY_DEPT_NAME | G27: Completed by department | H27: SINGLE_ASSESSMENT_FACT.csv
B28: 4167554 | C28: Advice given | D28: contact | E28: observation | F28: ﻿CNT_OUTCOME_ADVICE | G28: Outcome flag advice | H28: CONTACT_FACT.csv
B29: 44795391 | C29: CP investigation | D29: contact | E29: procedure_occurrence | F29: CNT_OUTCOME_CP_ENQUIRY | G29: Outcome flag CP (protected child) enquiry | H29: CONTACT_FACT.csv
B30: 44804300 | C30: Information dissemination and exchange | D30: contact | E30: observation | F30: CP_OUTCOME_EXISTING_REFERRAL | G30: Outcome flag existing referral | H30: CONTACT_FACT.csv
B31: 45881342 | C31: Missing child/infant | D31: contact | E31: measurement | F31: CNT_OUTCOME_MISSING | G31: Outcome flag missing | H31: CONTACT_FACT.csv
B32: 4144684 | C32: Patient referral | D32: contact | E32: procedure_occurrence | F32: CNT_OUTCOME_NEW_REFERRAL | G32: Outcome flag new referral | H32: CONTACT_FACT.csv
B33: 1620966 | C33: No further follow-up | D33: contact | E33: measurement | F33: CNT_OUTCOME_NFA | G33: Outcome flag no further action | H33: CONTACT_FACT.csv
B34: 4023148 | C34: Adoption | D34: contact | E34: observation | F34: CNT_OUTCOME_NON_AGENCY_ADOPTION | G34: Outcome flag non-agency adoption | H34: CONTACT_FACT.csv
B35: 4208655 | C35: Liasing with agency | D35: contact | E35: observation | F35: CNT_OUTCOME_OTHER_LOCAL_AUTH_CP | G35: Outcome flag other local authority | H35: CONTACT_FACT.csv
B36: 44811639 | C36: Child in private foster care | D36: contact | E36: observation | F36: CNT_OUTCOME_PRIVATE_FOSTERING | G36: Outcome flag private fostering | H36: CONTACT_FACT.csv
B37: N/A | C37: N/A | D37: contact | E37: observation | F37: CONTACT_DATE | G37: Date of contact | H37: CONTACT_FACT.csv
B38: N/A | C38: Map directly to response | D38: contact | E38: observation | F38: CONTACT_SOURCE | G38: Source of contact | H38: CONTACT_FACT.csv
B39: N/A | C39: Map as the provider associated with the procedure | D39: contact_provider | E39: provider | F39: DEPARTMENT | G39: Department | H39: CONTACT_FACT.csv
B40: N/A | C40: Map directly to response | D40: referral | E40: observation | F40: ﻿CONTACT_SOURCE | G40: Source of referral | H40: REFERRAL_FACT.csv
B41: N/A | C41: N/A | D41: referral_end | E41: observation | F41: REFERRAL_END_DATE | G41: Referral end date | H41: REFERRAL_FACT.csv
...

Sheet Responses
B2: Concept ID | C2: Mapping | D2: OMOP Table | E2: Table | F2: Variable | G2: Response
B3: 45879080 | C3: Primary | D3: {=INDEX(Fields!E:E, MATCH(1, (Fields!H:H=E3)*(Fields!F:F=F3), 0))} -> observation | E3: ADDRESS_HIST_DIM.csv | F3: ADDRESS_TYPE | G3: Current
B4: 37019469 | C4: Alternative | D4: {=INDEX(Fields!E:E, MATCH(1, (Fields!H:H=E4)*(Fields!F:F=F4), 0))} -> observation | E4: ADDRESS_HIST_DIM.csv | F4: ADDRESS_TYPE | G4: Placement
B5: 45879080 | C5: Primary | D5: {=INDEX(Fields!E:E, MATCH(1, (Fields!H:H=E5)*(Fields!F:F=F5), 0))} -> observation | E5: ADDRESS_HIST_DIM.csv | F5: ADDRESS_TYPE | G5: Primary
B6: 37019469 | C6: Alternative | D6: {=INDEX(Fields!E:E, MATCH(1, (Fields!H:H=E6)*(Fields!F:F=F6), 0))} -> observation | E6: ADDRESS_HIST_DIM.csv | F6: ADDRESS_TYPE | G6: Short Break Placement
B7: 46237191 | C7: General-Neglect or Abuse Suspected | D7: {=INDEX(Fields!E:E, MATCH(1, (Fields!H:H=E7)*(Fields!F:F=F7), 0))} -> observation | E7: CATEGORY_OF_NEED_FACT.csv | F7: ﻿CATEGORY_OF_NEED | G7: N1 - Abuse or neglect
B8: 4052648 | C8: Disability | D8: {=INDEX(Fields!E:E, MATCH(1, (Fields!H:H=E8)*(Fields!F:F=F8), 0))} -> observation | E8: CATEGORY_OF_NEED_FACT.csv | F8: ﻿CATEGORY_OF_NEED | G8: N2 - Disability
B9: 4142972 | C9: Family illness | D9: {=INDEX(Fields!E:E, MATCH(1, (Fields!H:H=E9)*(Fields!F:F=F9), 0))} -> observation | E9: CATEGORY_OF_NEED_FACT.csv | F9: ﻿CATEGORY_OF_NEED | G9: N3 - Parental Illness
B10: 36717118 | C10: Family distress | D10: {=INDEX(Fields!E:E, MATCH(1, (Fields!H:H=E10)*(Fields!F:F=F10), 0))} -> observation | E10: CATEGORY_OF_NEED_FACT.csv | F10: ﻿CATEGORY_OF_NEED | G10: N4 - Family in Acute Stress
B11: 4094126 | C11: Family problems | D11: {=INDEX(Fields!E:E, MATCH(1, (Fields!H:H=E11)*(Fields!F:F=F11), 0))} -> observation | E11: CATEGORY_OF_NEED_FACT.csv | F11: ﻿CATEGORY_OF_NEED | G11: N5 - Family Disfunction
B12: 4246609 | C12: Antisocial behavior | D12: {=INDEX(Fields!E:E, MATCH(1, (Fields!H:H=E12)*(Fields!F:F=F12), 0))} -> observation | E12: CATEGORY_OF_NEED_FACT.csv | F12: ﻿CATEGORY_OF_NEED | G12: N6 - Soc unacc behaviour
B13: 4310138 | C13: Low income | D13: {=INDEX(Fields!E:E, MATCH(1, (Fields!H:H=E13)*(Fields!F:F=F13), 0))} -> observation | E13: CATEGORY_OF_NEED_FACT.csv | F13: ﻿CATEGORY_OF_NEED | G13: N7 - Low income
B14: 4247382 | C14: Impaired parenting | D14: {=INDEX(Fields!E:E, MATCH(1, (Fields!H:H=E14)*(Fields!F:F=F14), 0))} -> observation | E14: CATEGORY_OF_NEED_FACT.csv | F14: ﻿CATEGORY_OF_NEED | G14: N8 - Absent parenting
... B138: 8507 | C138: MALE | D138: {=INDEX(Fields!E:E, MATCH(1, (Fields!H:H=E138)*(Fields!F:F=F138), 0))} -> observation | E138: PERSON_DIM.csv | F138: GENDER | G138: Male
B139: - | C139: do not map | D139: {=INDEX(Fields!E:E, MATCH(1, (Fields!H:H=E139)*(Fields!F:F=F139), 0))} -> observation | E139: PERSON_DIM.csv | F139: GENDER | G139: Unborn
B140: 4320153 | C140: Afghanistan | D140: {=INDEX(Fields!E:E, MATCH(1, (Fields!H:H=E140)*(Fields!F:F=F140), 0))} -> observation | E140: PERSON_DIM.csv | F140: NATIONALITY_DESCRIPTION | G140: Afghan
B141: 4320165 | C141: Albania | D141: {=INDEX(Fields!E:E, MATCH(1, (Fields!H:H=E141)*(Fields!F:F=F141), 0))} -> observation | E141: PERSON_DIM.csv | F141: NATIONALITY_DESCRIPTION | G141: Albanian
B142: 4072105 | C142: Algeria | D142: {=INDEX(Fields!E:E, MATCH(1, (Fields!H:H=E142)*(Fields!F:F=F142), 0))} -> observation | E142: PERSON_DIM.csv | F142: NATIONALITY_DESCRIPTION | G142: Algerian
B143: 4330442 | C143: United States of America | D143: {=INDEX(Fields!E:E, MATCH(1, (Fields!H:H=E143)*(Fields!F:F=F143), 0))} -> observation | E143: PERSON_DIM.csv | F143: NATIONALITY_DESCRIPTION | G143: American
B144: 4075205 | C144: Angola | D144: {=INDEX(Fields!E:E, MATCH(1, (Fields!H:H=E144)*(Fields!F:F=F144), 0))} -> observation | E144: PERSON_DIM.csv | F144: NATIONALITY_DESCRIPTION | G144: Angolan
B145: 4073750 | C145: Argentina | D145: {=INDEX(Fields!E:E, MATCH(1, (Fields!H:H=E145)*(Fields!F:F=F145), 0))} -> observation | E145: PERSON_DIM.csv | F145: NATIONALITY_DESCRIPTION | G145: Argentinian
B146: 41881315 | C146: Australia | D146: {=INDEX(Fields!E:E, MATCH(1, (Fields!H:H=E146)*(Fields!F:F=F146), 0))} -> observation | E146: PERSON_DIM.csv | F146: NATIONALITY_DESCRIPTION | G146: Australian
B147: 4329596 | C147: Austria | D147: {=INDEX(Fields!E:E, MATCH(1, (Fields!H:H=E147)*(Fields!F:F=F147), 0))} -> observation | E147: PERSON_DIM.csv | F147: NATIONALITY_DESCRIPTION | G147: Austrian
B148: 4329584 | C148: Bangladesh | D148: {=INDEX(Fields!E:E, MATCH(1, (Fields!H:H=E148)*(Fields!F:F=F148), 0))} -> observation | E148: PERSON_DIM.csv | F148: NATIONALITY_DESCRIPTION | G148: Bangladeshi
B149: 41890291 | C149: Belgium | D149: {=INDEX(Fields!E:E, MATCH(1, (Fields!H:H=E149)*(Fields!F:F=F149), 0))} -> observation | E149: PERSON_DIM.csv | F149: NATIONALITY_DESCRIPTION | G149: Belgian
B150: 41892130 | C150: Brazil | D150: {=INDEX(Fields!E:E, MATCH(1, (Fields!H:H=E150)*(Fields!F:F=F150), 0))} -> observation | E150: PERSON_DIM.csv | F150: NATIONALITY_DESCRIPTION | G150: Brazilian
B151: 42035286 | C151: United Kingdom | D151: {=INDEX(Fields!E:E, MATCH(1, (Fields!H:H=E151)*(Fields!F:F=F151), 0))} -> observation | E151: PERSON_DIM.csv | F151: NATIONALITY_DESCRIPTION | G151: British
... B276: 4258129 | C276: Referral by [qualitfier] Unknown | D276: {=INDEX(Fields!E:E, MATCH(1, (Fields!H:H=E276)*(Fields!F:F=F276), 0))} -> observation | E276: REFERRAL_FACT.csv | F276: ﻿CONTACT_SOURCE | G276: 9 - Anonymous

Sheet Original>>

Sheet Field Definitions
A1: Table | B1: Field | C1: Description
A2: CP_PLAN_FACT.csv | B2: ﻿CP_CATEGORY_DESC | C2: Description of protected child category
A3: CP_PLAN_FACT.csv | B3: CP_CATEGORY_EMOTIONAL | C3: CP reason flag emotional
A4: CP_PLAN_FACT.csv | B4: CP_CATEGORY_NEGLECT | C4: CP reason flag neglect
A5: CP_PLAN_FACT.csv | B5: CP_CATEGORY_PHYSICAL | C5: CP reason flag physical
A6: CP_PLAN_FACT.csv | B6: CP_CATEGORY_SEXUAL | C6: CP reason flag sexual
A7: CP_PLAN_FACT.csv | B7: CP_END_DATE | C7: End date
A8: CP_PLAN_FACT.csv | B8: CP_PLAN_ID | C8: Primary key. Unique ID per plan
A9: CP_PLAN_FACT.csv | B9: CP_START_DATE | C9: Start date
A10: CP_PLAN_FACT.csv | B10: rid | C10: research identifier
A11: CP_PLAN_FACT.csv | B11: trid | C11: transient research identifier
A12: CP_PLAN_FACT.csv | B12: REFERRAL_ID | C12: Foreign key to Referral
... A180: PERSON_DIM.csv | B180: _when_processed_utc | C180: Processing date/time
A182: S47_ENQUIRY_FACT.csv | B182: ﻿DIM_LOOKUP_STEP_SUMMARY_STATUS_DESC
A183: S47_ENQUIRY_FACT.csv | B183: PARENT_PATHWAY | C183: Source of enquiry?
A184: S47_ENQUIRY_FACT.csv | B184: rid | C184: research identifier
A185: S47_ENQUIRY_FACT.csv | B185: trid | C185: transient research identifier
A186: S47_ENQUIRY_FACT.csv | B186: REFERRAL_ID | C186: Foreign key to Referral
A187: S47_ENQUIRY_FACT.csv | B187: S47_ENQ_END_DATE | C187: Enquiry end date
A188: S47_ENQUIRY_FACT.csv | B188: S47_ENQ_OUTCOME_CP_CONFERENCE | C188: Outcome flag CP (protected child) conference
A189: S47_ENQUIRY_FACT.csv | B189: S47_ENQ_OUTCOME_LEGAL_ACTION | C189: Outcome flag legal action
A190: S47_ENQUIRY_FACT.csv | B190: S47_ENQ_OUTCOME_MONITOR | C190: Outcome flag monitor
A191: S47_ENQUIRY_FACT.csv | B191: S47_ENQ_OUTCOME_NFA_CONT_CORE_ASSESSMENT | C191: Outcome flag NFA continue core assessment
A192: S47_ENQUIRY_FACT.csv | B192: S47_ENQ_OUTCOME_NFA | C192: Outcome flag National Fostering Agency
A193: S47_ENQUIRY_FACT.csv | B193: S47_ENQ_OUTCOME_NFA_CONT_SINGLE_ASSESSMENT | C193: Outcome flag NFA continue single assessment
A194: S47_ENQUIRY_FACT.csv | B194: S47_ENQ_OUTCOME_PROV_OF_SHORT_BREAK_CARE | C194: Outcome flag provision of short break care
... A209: CATEGORY_OF_NEED_FACT.csv | B209: _when_processed-utc | C209: Processing date/time

Sheet Table Definitions
A1: Table | B1: Description
A2: CP_PLAN_FACT.csv | B2: Protected children
A3: STRATEGY_DISCUSSION_FACT.csv | B3: Strategy discussions.
A4: SINGLE_ASSESSMENT_FACT.csv | B4: Assessment outcomes.
A5: CONTACT_FACT.csv | B5: Contacts
A6: REFERRAL_FACT.csv | B6: Referrals
A7: CLA_FACT.csv | B7: Looked after children
A8: EARLY_HELP_CONTACT_FACT.csv | B8: Early Help contacts
A9: ASSESSMENT_FORM_FACT.csv | B9: Assessment measurements
A10: ADDRESS_HIST_DIM.csv | B10: Address information
A11: DISBAILITY_FACT.csv | B11: Disability information
A12: LANGUAGE_FACT.csv | B12: Language information
... A15: CATEGORY_OF_NEED_FACT.csv | B15: Children in need of care episodes
